<?xml version="1.0"?>
<robot xmlns:xacro="http://www.ros.org/wiki/xacro"  name="robot">

    <xacro:include filename="inertial_macros.xacro"/> <!-- Include the inertial macros for calculating inertia properties of links. -->
    <xacro:include filename="gazebo_control.xacro"/> <!-- Include the gazebo control macros for controlling the robot in Gazebo. -->

    <!-- materials -->
    <material name="grey">
        <color rgba="0.2 0.2 0.2 1"/>
    </material>

    <material name="white">
        <color rgba=".9 .9 .9 .2"/>
    </material>

    <material name="orange">
        <color rgba="1 0.3 0.1 1"/>
    </material>

    <material name="blue">
        <color rgba="0 0 1 1"/>
    </material>


    <!-- This is a simple balancing bot with a base, two wheels, and a caster wheel. -->
    <link name="base_link">
        <xacro:inertial_box mass="0.01" x="0.1" y="0.1" z="0.1">
            <origin xyz="0 0 0" rpy="0 0 0"/>
        </xacro:inertial_box>
    </link>

    <joint name="base_to_base2_joint" type="continuous">
        <parent link="base_link"/>
        <child link="base2_link"/>
        <axis xyz="0 1 0"/>
        <origin rpy="0 0 0" xyz="0 0 0"/>
    </joint>

    <link name="base2_link">
        <xacro:inertial_box mass="0.01" x="0.1" y="0.1" z="0.1">
            <origin xyz="0 0 0" rpy="0 0 0"/>
        </xacro:inertial_box>
    </link>

    <joint name="base2_to_frame_joint" type="fixed">
        <parent link="base2_link"/>
        <child link="frame_link"/>
        <origin rpy="0 0 0" xyz="0 0 .105"/>
    </joint>

    <link name="frame_link">
        <visual>
            <origin xyz="0 0 -.06" rpy="0 0 0"/>
            <geometry>
                <box size=".03 .1 .12" />
            </geometry>
            <material name="white" />
        </visual>
        <collision>
            <origin xyz="0 0 -.06" rpy="0 0 0"/>
            <geometry>
                <box size=".03 .1 .12" />
            </geometry>
        </collision>
        <xacro:inertial_box mass="0.05" x=".03" y=".1" z=".12">
            <origin xyz="0 0 -.06" rpy="0 0 0"/>
        </xacro:inertial_box>
    </link>

    <joint name="left_wheel_joint" type="continuous">
        <parent link="base2_link"/>
        <child link="left_wheel_link"/>
        <origin xyz="0 0.07 0" rpy="-${pi/2} 0 0"/>
        <axis xyz="0 0 1">
            <limit effort="10"/>
        </axis>
    </joint>

    <link name="left_wheel_link">
        <visual>
            <geometry>
                <cylinder length="0.025" radius="0.025" />
            </geometry>
            <material name="blue"/>
        </visual>
        <collision>
            <origin xyz="0 0 0" rpy="0 0 0"/>
            <geometry>
                <cylinder length="0.025" radius="0.025" />
            </geometry>
        </collision>
        <xacro:inertial_cylinder mass="0.05" length=".025" radius=".025">
            <origin xyz="0 0 0" rpy="0 0 0"/>
        </xacro:inertial_cylinder>
    </link>

    <joint name="right_wheel_joint" type="continuous">
        <parent link="base2_link"/>
        <child link="right_wheel_link"/>
        <origin xyz="0 -0.07 0" rpy="-${pi/2} 0 0"/>
        <axis xyz="0 0 1">
            <limit effort="10"/>
        </axis>
    </joint>

    <link name="right_wheel_link">
        <visual>
            <geometry>
                <cylinder length="0.025" radius="0.025" />
            </geometry>
            <material name="blue"/>
        </visual>
        <collision>
            <origin xyz="0 0 0" rpy="0 0 0"/>
            <geometry>
                <cylinder length="0.025" radius="0.025" />
            </geometry>
        </collision>
        <xacro:inertial_cylinder mass="0.05" length=".025" radius=".025">
            <origin xyz="0 0 0" rpy="0 0 0"/>
        </xacro:inertial_cylinder>
    </link>

    <joint name="caster_wheel_joint" type="fixed">
        <parent link="frame_link"/>
        <child link="caster_wheel_link"/>
        <origin xyz="0.0125 0 0" rpy="0 0 0"/>
    </joint>

    <link name="caster_wheel_link">
        <visual>
            <geometry>
                <sphere radius="0.0125" />
            </geometry>
            <!-- <material name="blue"/> -->
        </visual>
        <collision>
            <origin xyz="0 0 0" rpy="0 0 0"/>
            <geometry>
                <sphere radius="0.0125" />
            </geometry>
        </collision>
        <xacro:inertial_sphere mass="0.1" radius="0.0125">
            <origin xyz="0 0 0" rpy="0 0 0"/>
        </xacro:inertial_sphere>
    </link>

    <gazebo reference="caster_wheel_link">
        <material>Gazebo/White</material>
        <mu1 value="0.001"/>
        <mu2 value="0.001"/>
    </gazebo>
    <gazebo reference="left_wheel_link">
        <mu1 value="0.85"/>
        <mu2 value="0.85"/>
    </gazebo>
    <gazebo reference="right_wheel_link">
        <mu1 value="0.85"/>
        <mu2 value="0.85"/>
    </gazebo>


</robot>
